[2023-02-07T11:30:03.108+0000] {taskinstance.py:1083} INFO - Dependencies all met for <TaskInstance: data_ingestion_gcs_dag.process_spark.spark_transform_sparksubmit scheduled__2023-02-06T00:00:00+00:00 [queued]>
[2023-02-07T11:30:03.129+0000] {taskinstance.py:1083} INFO - Dependencies all met for <TaskInstance: data_ingestion_gcs_dag.process_spark.spark_transform_sparksubmit scheduled__2023-02-06T00:00:00+00:00 [queued]>
[2023-02-07T11:30:03.130+0000] {taskinstance.py:1279} INFO - 
--------------------------------------------------------------------------------
[2023-02-07T11:30:03.130+0000] {taskinstance.py:1280} INFO - Starting attempt 1 of 2
[2023-02-07T11:30:03.130+0000] {taskinstance.py:1281} INFO - 
--------------------------------------------------------------------------------
[2023-02-07T11:30:03.159+0000] {taskinstance.py:1300} INFO - Executing <Task(DataprocSubmitJobOperator): process_spark.spark_transform_sparksubmit> on 2023-02-06 00:00:00+00:00
[2023-02-07T11:30:03.173+0000] {standard_task_runner.py:55} INFO - Started process 136 to run task
[2023-02-07T11:30:03.180+0000] {standard_task_runner.py:82} INFO - Running: ['***', 'tasks', 'run', 'data_ingestion_gcs_dag', 'process_spark.spark_transform_sparksubmit', 'scheduled__2023-02-06T00:00:00+00:00', '--job-id', '15', '--raw', '--subdir', 'DAGS_FOLDER/covid19_pipeline.py', '--cfg-path', '/tmp/tmp4p22lsa4']
[2023-02-07T11:30:03.181+0000] {standard_task_runner.py:83} INFO - Job 15: Subtask process_spark.spark_transform_sparksubmit
[2023-02-07T11:30:03.307+0000] {task_command.py:388} INFO - Running <TaskInstance: data_ingestion_gcs_dag.process_spark.spark_transform_sparksubmit scheduled__2023-02-06T00:00:00+00:00 [running]> on host 148f29fbd44c
[2023-02-07T11:30:03.471+0000] {taskinstance.py:1509} INFO - Exporting the following env vars:
AIRFLOW_CTX_DAG_OWNER=***
AIRFLOW_CTX_DAG_ID=data_ingestion_gcs_dag
AIRFLOW_CTX_TASK_ID=process_spark.spark_transform_sparksubmit
AIRFLOW_CTX_EXECUTION_DATE=2023-02-06T00:00:00+00:00
AIRFLOW_CTX_TRY_NUMBER=1
AIRFLOW_CTX_DAG_RUN_ID=scheduled__2023-02-06T00:00:00+00:00
[2023-02-07T11:30:03.476+0000] {dataproc.py:1866} INFO - Submitting job
[2023-02-07T11:30:03.478+0000] {crypto.py:83} WARNING - empty cryptography key - values will not be stored encrypted.
[2023-02-07T11:30:03.478+0000] {base.py:73} INFO - Using connection ID 'google_cloud_default' for task execution.
[2023-02-07T11:30:03.649+0000] {taskinstance.py:1768} ERROR - Task failed with exception
Traceback (most recent call last):
  File "/home/airflow/.local/lib/python3.7/site-packages/google/api_core/grpc_helpers.py", line 50, in error_remapped_callable
    return callable_(*args, **kwargs)
  File "/home/airflow/.local/lib/python3.7/site-packages/grpc/_channel.py", line 946, in __call__
    return _end_unary_response_blocking(state, call, False, None)
  File "/home/airflow/.local/lib/python3.7/site-packages/grpc/_channel.py", line 849, in _end_unary_response_blocking
    raise _InactiveRpcError(state)
grpc._channel._InactiveRpcError: <_InactiveRpcError of RPC that terminated with:
	status = StatusCode.PERMISSION_DENIED
	details = "Cloud Dataproc API has not been used in project 681627448883 before or it is disabled. Enable it by visiting https://console.developers.google.com/apis/api/dataproc.googleapis.com/overview?project=681627448883 then retry. If you enabled this API recently, wait a few minutes for the action to propagate to our systems and retry."
	debug_error_string = "UNKNOWN:Error received from peer ipv4:142.251.12.95:443 {grpc_message:"Cloud Dataproc API has not been used in project 681627448883 before or it is disabled. Enable it by visiting https://console.developers.google.com/apis/api/dataproc.googleapis.com/overview?project=681627448883 then retry. If you enabled this API recently, wait a few minutes for the action to propagate to our systems and retry.", grpc_status:7, created_time:"2023-02-07T11:30:03.647825793+00:00"}"
>

The above exception was the direct cause of the following exception:

Traceback (most recent call last):
  File "/home/airflow/.local/lib/python3.7/site-packages/airflow/providers/google/cloud/operators/dataproc.py", line 1875, in execute
    metadata=self.metadata,
  File "/home/airflow/.local/lib/python3.7/site-packages/airflow/providers/google/common/hooks/base_google.py", line 462, in inner_wrapper
    return func(self, *args, **kwargs)
  File "/home/airflow/.local/lib/python3.7/site-packages/airflow/providers/google/cloud/hooks/dataproc.py", line 784, in submit_job
    metadata=metadata,
  File "/home/airflow/.local/lib/python3.7/site-packages/google/cloud/dataproc_v1/services/job_controller/client.py", line 524, in submit_job
    metadata=metadata,
  File "/home/airflow/.local/lib/python3.7/site-packages/google/api_core/gapic_v1/method.py", line 154, in __call__
    return wrapped_func(*args, **kwargs)
  File "/home/airflow/.local/lib/python3.7/site-packages/google/api_core/retry.py", line 288, in retry_wrapped_func
    on_error=on_error,
  File "/home/airflow/.local/lib/python3.7/site-packages/google/api_core/retry.py", line 190, in retry_target
    return target()
  File "/home/airflow/.local/lib/python3.7/site-packages/google/api_core/grpc_helpers.py", line 52, in error_remapped_callable
    raise exceptions.from_grpc_error(exc) from exc
google.api_core.exceptions.PermissionDenied: 403 Cloud Dataproc API has not been used in project 681627448883 before or it is disabled. Enable it by visiting https://console.developers.google.com/apis/api/dataproc.googleapis.com/overview?project=681627448883 then retry. If you enabled this API recently, wait a few minutes for the action to propagate to our systems and retry. [links {
  description: "Google developers console API activation"
  url: "https://console.developers.google.com/apis/api/dataproc.googleapis.com/overview?project=681627448883"
}
, reason: "SERVICE_DISABLED"
domain: "googleapis.com"
metadata {
  key: "consumer"
  value: "projects/681627448883"
}
metadata {
  key: "service"
  value: "dataproc.googleapis.com"
}
]
[2023-02-07T11:30:03.668+0000] {taskinstance.py:1323} INFO - Marking task as UP_FOR_RETRY. dag_id=data_ingestion_gcs_dag, task_id=process_spark.spark_transform_sparksubmit, execution_date=20230206T000000, start_date=20230207T113003, end_date=20230207T113003
[2023-02-07T11:30:03.691+0000] {standard_task_runner.py:105} ERROR - Failed to execute job 15 for task process_spark.spark_transform_sparksubmit (403 Cloud Dataproc API has not been used in project 681627448883 before or it is disabled. Enable it by visiting https://console.developers.google.com/apis/api/dataproc.googleapis.com/overview?project=681627448883 then retry. If you enabled this API recently, wait a few minutes for the action to propagate to our systems and retry. [links {
  description: "Google developers console API activation"
  url: "https://console.developers.google.com/apis/api/dataproc.googleapis.com/overview?project=681627448883"
}
, reason: "SERVICE_DISABLED"
domain: "googleapis.com"
metadata {
  key: "consumer"
  value: "projects/681627448883"
}
metadata {
  key: "service"
  value: "dataproc.googleapis.com"
}
]; 136)
[2023-02-07T11:30:03.713+0000] {local_task_job.py:208} INFO - Task exited with return code 1
