[2023-02-07T11:29:58.689+0000] {taskinstance.py:1083} INFO - Dependencies all met for <TaskInstance: data_ingestion_gcs_dag.process_spark.create_dataproc_cluster scheduled__2023-02-06T00:00:00+00:00 [queued]>
[2023-02-07T11:29:58.718+0000] {taskinstance.py:1083} INFO - Dependencies all met for <TaskInstance: data_ingestion_gcs_dag.process_spark.create_dataproc_cluster scheduled__2023-02-06T00:00:00+00:00 [queued]>
[2023-02-07T11:29:58.718+0000] {taskinstance.py:1279} INFO - 
--------------------------------------------------------------------------------
[2023-02-07T11:29:58.719+0000] {taskinstance.py:1280} INFO - Starting attempt 2 of 2
[2023-02-07T11:29:58.720+0000] {taskinstance.py:1281} INFO - 
--------------------------------------------------------------------------------
[2023-02-07T11:29:58.749+0000] {taskinstance.py:1300} INFO - Executing <Task(DataprocCreateClusterOperator): process_spark.create_dataproc_cluster> on 2023-02-06 00:00:00+00:00
[2023-02-07T11:29:58.765+0000] {standard_task_runner.py:55} INFO - Started process 119 to run task
[2023-02-07T11:29:58.773+0000] {standard_task_runner.py:82} INFO - Running: ['***', 'tasks', 'run', 'data_ingestion_gcs_dag', 'process_spark.create_dataproc_cluster', 'scheduled__2023-02-06T00:00:00+00:00', '--job-id', '14', '--raw', '--subdir', 'DAGS_FOLDER/covid19_pipeline.py', '--cfg-path', '/tmp/tmpx_7eqk10']
[2023-02-07T11:29:58.774+0000] {standard_task_runner.py:83} INFO - Job 14: Subtask process_spark.create_dataproc_cluster
[2023-02-07T11:29:58.918+0000] {task_command.py:388} INFO - Running <TaskInstance: data_ingestion_gcs_dag.process_spark.create_dataproc_cluster scheduled__2023-02-06T00:00:00+00:00 [running]> on host 148f29fbd44c
[2023-02-07T11:29:59.187+0000] {taskinstance.py:1509} INFO - Exporting the following env vars:
AIRFLOW_CTX_DAG_OWNER=***
AIRFLOW_CTX_DAG_ID=data_ingestion_gcs_dag
AIRFLOW_CTX_TASK_ID=process_spark.create_dataproc_cluster
AIRFLOW_CTX_EXECUTION_DATE=2023-02-06T00:00:00+00:00
AIRFLOW_CTX_TRY_NUMBER=2
AIRFLOW_CTX_DAG_RUN_ID=scheduled__2023-02-06T00:00:00+00:00
[2023-02-07T11:29:59.192+0000] {dataproc.py:591} INFO - Creating cluster: covid19-process-cluster
[2023-02-07T11:29:59.199+0000] {crypto.py:83} WARNING - empty cryptography key - values will not be stored encrypted.
[2023-02-07T11:29:59.200+0000] {base.py:73} INFO - Using connection ID 'google_cloud_default' for task execution.
[2023-02-07T11:29:59.636+0000] {taskinstance.py:1768} ERROR - Task failed with exception
Traceback (most recent call last):
  File "/home/airflow/.local/lib/python3.7/site-packages/google/api_core/grpc_helpers.py", line 50, in error_remapped_callable
    return callable_(*args, **kwargs)
  File "/home/airflow/.local/lib/python3.7/site-packages/grpc/_channel.py", line 946, in __call__
    return _end_unary_response_blocking(state, call, False, None)
  File "/home/airflow/.local/lib/python3.7/site-packages/grpc/_channel.py", line 849, in _end_unary_response_blocking
    raise _InactiveRpcError(state)
grpc._channel._InactiveRpcError: <_InactiveRpcError of RPC that terminated with:
	status = StatusCode.PERMISSION_DENIED
	details = "Cloud Dataproc API has not been used in project 681627448883 before or it is disabled. Enable it by visiting https://console.developers.google.com/apis/api/dataproc.googleapis.com/overview?project=681627448883 then retry. If you enabled this API recently, wait a few minutes for the action to propagate to our systems and retry."
	debug_error_string = "UNKNOWN:Error received from peer ipv4:172.217.194.95:443 {created_time:"2023-02-07T11:29:59.634690825+00:00", grpc_status:7, grpc_message:"Cloud Dataproc API has not been used in project 681627448883 before or it is disabled. Enable it by visiting https://console.developers.google.com/apis/api/dataproc.googleapis.com/overview?project=681627448883 then retry. If you enabled this API recently, wait a few minutes for the action to propagate to our systems and retry."}"
>

The above exception was the direct cause of the following exception:

Traceback (most recent call last):
  File "/home/airflow/.local/lib/python3.7/site-packages/airflow/providers/google/cloud/operators/dataproc.py", line 599, in execute
    cluster = self._create_cluster(hook)
  File "/home/airflow/.local/lib/python3.7/site-packages/airflow/providers/google/cloud/operators/dataproc.py", line 532, in _create_cluster
    metadata=self.metadata,
  File "/home/airflow/.local/lib/python3.7/site-packages/airflow/providers/google/common/hooks/base_google.py", line 462, in inner_wrapper
    return func(self, *args, **kwargs)
  File "/home/airflow/.local/lib/python3.7/site-packages/airflow/providers/google/cloud/hooks/dataproc.py", line 331, in create_cluster
    metadata=metadata,
  File "/home/airflow/.local/lib/python3.7/site-packages/google/cloud/dataproc_v1/services/cluster_controller/client.py", line 564, in create_cluster
    metadata=metadata,
  File "/home/airflow/.local/lib/python3.7/site-packages/google/api_core/gapic_v1/method.py", line 154, in __call__
    return wrapped_func(*args, **kwargs)
  File "/home/airflow/.local/lib/python3.7/site-packages/google/api_core/retry.py", line 288, in retry_wrapped_func
    on_error=on_error,
  File "/home/airflow/.local/lib/python3.7/site-packages/google/api_core/retry.py", line 190, in retry_target
    return target()
  File "/home/airflow/.local/lib/python3.7/site-packages/google/api_core/timeout.py", line 99, in func_with_timeout
    return func(*args, **kwargs)
  File "/home/airflow/.local/lib/python3.7/site-packages/google/api_core/grpc_helpers.py", line 52, in error_remapped_callable
    raise exceptions.from_grpc_error(exc) from exc
google.api_core.exceptions.PermissionDenied: 403 Cloud Dataproc API has not been used in project 681627448883 before or it is disabled. Enable it by visiting https://console.developers.google.com/apis/api/dataproc.googleapis.com/overview?project=681627448883 then retry. If you enabled this API recently, wait a few minutes for the action to propagate to our systems and retry. [links {
  description: "Google developers console API activation"
  url: "https://console.developers.google.com/apis/api/dataproc.googleapis.com/overview?project=681627448883"
}
, reason: "SERVICE_DISABLED"
domain: "googleapis.com"
metadata {
  key: "consumer"
  value: "projects/681627448883"
}
metadata {
  key: "service"
  value: "dataproc.googleapis.com"
}
]
[2023-02-07T11:29:59.676+0000] {taskinstance.py:1323} INFO - Marking task as FAILED. dag_id=data_ingestion_gcs_dag, task_id=process_spark.create_dataproc_cluster, execution_date=20230206T000000, start_date=20230207T112958, end_date=20230207T112959
[2023-02-07T11:29:59.749+0000] {standard_task_runner.py:105} ERROR - Failed to execute job 14 for task process_spark.create_dataproc_cluster (403 Cloud Dataproc API has not been used in project 681627448883 before or it is disabled. Enable it by visiting https://console.developers.google.com/apis/api/dataproc.googleapis.com/overview?project=681627448883 then retry. If you enabled this API recently, wait a few minutes for the action to propagate to our systems and retry. [links {
  description: "Google developers console API activation"
  url: "https://console.developers.google.com/apis/api/dataproc.googleapis.com/overview?project=681627448883"
}
, reason: "SERVICE_DISABLED"
domain: "googleapis.com"
metadata {
  key: "consumer"
  value: "projects/681627448883"
}
metadata {
  key: "service"
  value: "dataproc.googleapis.com"
}
]; 119)
[2023-02-07T11:29:59.824+0000] {local_task_job.py:208} INFO - Task exited with return code 1
