[2023-02-07T12:25:32.429+0000] {taskinstance.py:1083} INFO - Dependencies all met for <TaskInstance: data_ingestion_gcs_dag.process_spark.create_dataproc_cluster scheduled__2023-02-06T00:00:00+00:00 [queued]>
[2023-02-07T12:25:32.443+0000] {taskinstance.py:1083} INFO - Dependencies all met for <TaskInstance: data_ingestion_gcs_dag.process_spark.create_dataproc_cluster scheduled__2023-02-06T00:00:00+00:00 [queued]>
[2023-02-07T12:25:32.443+0000] {taskinstance.py:1279} INFO - 
--------------------------------------------------------------------------------
[2023-02-07T12:25:32.443+0000] {taskinstance.py:1280} INFO - Starting attempt 5 of 6
[2023-02-07T12:25:32.443+0000] {taskinstance.py:1281} INFO - 
--------------------------------------------------------------------------------
[2023-02-07T12:25:32.462+0000] {taskinstance.py:1300} INFO - Executing <Task(DataprocCreateClusterOperator): process_spark.create_dataproc_cluster> on 2023-02-06 00:00:00+00:00
[2023-02-07T12:25:32.473+0000] {standard_task_runner.py:55} INFO - Started process 138 to run task
[2023-02-07T12:25:32.479+0000] {standard_task_runner.py:82} INFO - Running: ['***', 'tasks', 'run', 'data_ingestion_gcs_dag', 'process_spark.create_dataproc_cluster', 'scheduled__2023-02-06T00:00:00+00:00', '--job-id', '24', '--raw', '--subdir', 'DAGS_FOLDER/covid19_pipeline.py', '--cfg-path', '/tmp/tmp8qek8vj2']
[2023-02-07T12:25:32.479+0000] {standard_task_runner.py:83} INFO - Job 24: Subtask process_spark.create_dataproc_cluster
[2023-02-07T12:25:32.572+0000] {task_command.py:388} INFO - Running <TaskInstance: data_ingestion_gcs_dag.process_spark.create_dataproc_cluster scheduled__2023-02-06T00:00:00+00:00 [running]> on host d495a5b68c8b
[2023-02-07T12:25:32.675+0000] {taskinstance.py:1509} INFO - Exporting the following env vars:
AIRFLOW_CTX_DAG_OWNER=***
AIRFLOW_CTX_DAG_ID=data_ingestion_gcs_dag
AIRFLOW_CTX_TASK_ID=process_spark.create_dataproc_cluster
AIRFLOW_CTX_EXECUTION_DATE=2023-02-06T00:00:00+00:00
AIRFLOW_CTX_TRY_NUMBER=5
AIRFLOW_CTX_DAG_RUN_ID=scheduled__2023-02-06T00:00:00+00:00
[2023-02-07T12:25:32.682+0000] {dataproc.py:591} INFO - Creating cluster: covid19-process-cluster
[2023-02-07T12:25:32.683+0000] {crypto.py:83} WARNING - empty cryptography key - values will not be stored encrypted.
[2023-02-07T12:25:32.684+0000] {base.py:73} INFO - Using connection ID 'google_cloud_default' for task execution.
[2023-02-07T12:25:36.165+0000] {taskinstance.py:1768} ERROR - Task failed with exception
Traceback (most recent call last):
  File "/home/airflow/.local/lib/python3.7/site-packages/google/api_core/grpc_helpers.py", line 50, in error_remapped_callable
    return callable_(*args, **kwargs)
  File "/home/airflow/.local/lib/python3.7/site-packages/grpc/_channel.py", line 946, in __call__
    return _end_unary_response_blocking(state, call, False, None)
  File "/home/airflow/.local/lib/python3.7/site-packages/grpc/_channel.py", line 849, in _end_unary_response_blocking
    raise _InactiveRpcError(state)
grpc._channel._InactiveRpcError: <_InactiveRpcError of RPC that terminated with:
	status = StatusCode.NOT_FOUND
	details = "Google Cloud Storage object does not exist 'gs://goog-dataproc-initialization-asia-southeast2/python/pip-install.sh'."
	debug_error_string = "UNKNOWN:Error received from peer ipv4:172.253.118.95:443 {created_time:"2023-02-07T12:25:36.164477403+00:00", grpc_status:5, grpc_message:"Google Cloud Storage object does not exist \'gs://goog-dataproc-initialization-asia-southeast2/python/pip-install.sh\'."}"
>

The above exception was the direct cause of the following exception:

Traceback (most recent call last):
  File "/home/airflow/.local/lib/python3.7/site-packages/airflow/providers/google/cloud/operators/dataproc.py", line 599, in execute
    cluster = self._create_cluster(hook)
  File "/home/airflow/.local/lib/python3.7/site-packages/airflow/providers/google/cloud/operators/dataproc.py", line 532, in _create_cluster
    metadata=self.metadata,
  File "/home/airflow/.local/lib/python3.7/site-packages/airflow/providers/google/common/hooks/base_google.py", line 462, in inner_wrapper
    return func(self, *args, **kwargs)
  File "/home/airflow/.local/lib/python3.7/site-packages/airflow/providers/google/cloud/hooks/dataproc.py", line 331, in create_cluster
    metadata=metadata,
  File "/home/airflow/.local/lib/python3.7/site-packages/google/cloud/dataproc_v1/services/cluster_controller/client.py", line 564, in create_cluster
    metadata=metadata,
  File "/home/airflow/.local/lib/python3.7/site-packages/google/api_core/gapic_v1/method.py", line 154, in __call__
    return wrapped_func(*args, **kwargs)
  File "/home/airflow/.local/lib/python3.7/site-packages/google/api_core/retry.py", line 288, in retry_wrapped_func
    on_error=on_error,
  File "/home/airflow/.local/lib/python3.7/site-packages/google/api_core/retry.py", line 190, in retry_target
    return target()
  File "/home/airflow/.local/lib/python3.7/site-packages/google/api_core/timeout.py", line 99, in func_with_timeout
    return func(*args, **kwargs)
  File "/home/airflow/.local/lib/python3.7/site-packages/google/api_core/grpc_helpers.py", line 52, in error_remapped_callable
    raise exceptions.from_grpc_error(exc) from exc
google.api_core.exceptions.NotFound: 404 Google Cloud Storage object does not exist 'gs://goog-dataproc-initialization-asia-southeast2/python/pip-install.sh'.
[2023-02-07T12:25:36.181+0000] {taskinstance.py:1323} INFO - Marking task as UP_FOR_RETRY. dag_id=data_ingestion_gcs_dag, task_id=process_spark.create_dataproc_cluster, execution_date=20230206T000000, start_date=20230207T122532, end_date=20230207T122536
[2023-02-07T12:25:36.200+0000] {standard_task_runner.py:105} ERROR - Failed to execute job 24 for task process_spark.create_dataproc_cluster (404 Google Cloud Storage object does not exist 'gs://goog-dataproc-initialization-asia-southeast2/python/pip-install.sh'.; 138)
[2023-02-07T12:25:36.227+0000] {local_task_job.py:208} INFO - Task exited with return code 1
